<mujocoinclude>
  <body name="arm_base" childclass="airbot_play" gravcomp="1">
    <site name="armbase"/>
    <geom mesh="arm_base_0" pos="0 0 -0.0015" material="Gree_Light_Base" class="visual"/>
    <geom mesh="arm_base_1" material="Paint_Matte_Black" class="visual"/>
    <body name="link1" pos="0 0 0.1172" gravcomp="1">
      <inertial pos="7.9126e-05 -0.002527 -0.0041359" quat="0.696716 0.716558 0.0238919 -0.0236876" mass="0.54639" diaginertia="0.000346294 0.000325437 0.000286269"/>
      <joint name="joint1" class="joint1"/>
      <geom type="mesh" material="Paint_Matte_Black" mesh="link1" class="visual"/>
      <body name="link2" quat="0.135866 0.135867 -0.69393 0.693932" gravcomp="1">
        <inertial pos="0.22493 0.0047721 0.008023" quat="-0.210875 0.632473 -0.273056 0.693506" mass="0.64621" diaginertia="0.00516535 0.00505042 0.000418626"/>
        <joint name="joint2" class="joint2"/>
        <geom type="box" pos="0.08 0.015 0" euler="0 0 0.15" size="0.11 0.03 0.04" rgba="1 0 0 1" class="collision"/>
        <geom type="box" pos="0.235 0.015 0" euler="0 0 -0.3" size="0.065 0.025 0.045" rgba="1 0 0 1" class="collision"/>
        <geom mesh="link2_0" material="Paint_Matte_Black" class="visual"/>
        <geom mesh="link2_1" material="Paint_Metallic_White" class="visual"/>
        <body name="link3" pos="0.27009 0 0" quat="0.192144 0 0 -0.981367" gravcomp="1">
          <inertial pos="0.16813 -5.5576e-05 0.0031184" quat="0.511278 0.488423 0.489191 0.510617" mass="0.26829" diaginertia="0.0031527 0.0030951 0.000239403"/>
          <joint name="joint3" class="joint3"/>
          <geom type="box" pos="0.13 0 0" size="0.13 0.025 0.025" rgba="1 0 0 1" class="collision"/>
          <geom mesh="link3_0" material="Paint_Matte_Black" class="visual"/>
          <geom mesh="link3_1" material="Paint_Metallic_White" class="visual"/>
          <body name="link4" pos="0.29015 0 0" quat="-2.59734e-06 0.707105 2.59735e-06 0.707108" gravcomp="1">
            <inertial pos="5.2436e-06 0.00040412 -0.03228" quat="0.999969 -0.000174762 -0.00792041 -6.98144e-05" mass="0.34876" diaginertia="0.000423574 0.000412 0.000126826"/>
            <joint name="joint4" class="joint4"/>
            <geom type="mesh" material="Paint_Matte_Black" mesh="link4" class="visual"/>
            <body name="link5" quat="0.707105 0.707108 0 0" gravcomp="1">
              <inertial pos="8.3328e-06 0.026148 0.002525" quat="0.531568 0.4663 0.4663 0.531568" mass="0.36132" diaginertia="0.0004677 0.000432922 0.000178178"/>
              <joint name="joint5" class="joint5"/>
              <geom mesh="link5_0" material="Paint_Matte_Black" class="visual"/>
              <geom mesh="link5_1" material="Paint_Metallic_White" class="visual"/>
              <body name="link6" pos="0 0.23645 0" quat="0.499998 -0.5 0.5 0.500002" gravcomp="1">
                <inertial pos="3.54807e-05 -0.00259012 -0.120604" quat="0.699294 -0.0373828 0.0386404 0.712809" mass="0.617009" diaginertia="0.00236094 0.00225984 0.000562288"/>
                <joint name="joint6" class="joint6"/>
                <geom name="hand_box" type="box" pos="0 0 -0.07" size="0.025 0.08 0.015" rgba="1 0 0 1" class="collision"/>
                <geom type="mesh" material="Paint_Matte_Black" mesh="link6" class="visual"/>
                <geom type="mesh" material="Paint_Matte_Black" mesh="camera_stand" class="visual"/>
                <site name="endpoint" pos='0 0 0.023' euler="0 0 1.5708"/>
                <body name="left" gravcomp="1">
                  <inertial pos="0 0.018307 -0.012505" quat="0.95 0.1 0 0" mass="0.027004" diaginertia="2.55732e-05 2.9e-05 1.12468e-05"/>
                  <joint name="endleft" class='finger_left'/>
                  <geom type="mesh" mesh="left" material="Paint_Matte_Black" class="visual"/>
                  <geom name="left_finger_pad" type="box" size=".00625 .005 .019" pos="0 0.005 0.005" rgba="1 0 0 1" class="collision"/>
                  <geom type="box" size=".015 .005 .018" pos="0 0.005 -0.032" rgba="1 0 0 1" class="collision"/>
                </body>
                <body name="right" gravcomp="1">
                  <inertial pos="0 -0.018307 -0.012505" quat="0.95 -0.1 0 0" mass="0.027004" diaginertia="2.550732e-05 2.9e-05 1.124468e-05"/>
                  <joint name="endright" class="finger_right"/>
                  <geom type="mesh" mesh="right" material="Paint_Matte_Black" class="visual"/>
                  <geom name="right_finger_pad" type="box" size=".00625 .005 .019" pos="0 -0.005 0.005" rgba="1 0 0 1" class="collision"/>
                  <geom type="box" size=".015 .005 .018" pos="0 -0.005 -0.032" rgba="1 0 0 1" class="collision"/>
                </body>
              </body>
            </body>
          </body>
        </body>
      </body>
    </body>
  </body>
</mujocoinclude>
